Workbook

Sheet README
A1: ACCESSPATH - PILOT DATA SCAFFOLD v0.2
A2: Virginia Tech, Blacksburg - Drillfield + North Academic District
A4: READ THIS FIRST
A5: Nobody has surveyed this campus for this file. | B5: Building coordinates are real and official. Almost nothing else is.
A6: Every accessibility value here is UNKNOWN. | B6: The display_tier column says so on every row. Zero rows are CONFIRMED for accessibility.
A7: Do not ship this to end users as-is. | B7: It is a schema and topology scaffold for wiring up routing, not a description of the built environment.
A8: The fix is in the Field Survey tab. | B8: About two hours of walking converts ~15 rows from UNKNOWN to CONFIRMED and makes the demo honest.
A10: HOW 'CONFIRMED' vs 'UNKNOWN' WORKS
A11: display_tier is a formula, not a typed value. | B11: It reads: CONFIRMED when confidence is "official" or "field_verified", otherwise UNKNOWN. Change confidence and the tier follows.
A12: Render the two tiers differently. | B12: Solid line / filled pin for CONFIRMED. Dashed line / hollow pin, plus the word 'Unverified', for UNKNOWN. Never let them look the same.
A13: 'inferred' means Claude guessed it. | B13: Treat inferred exactly as unknown when routing. It is not a weak yes - it is a no-data marker with a hint attached.
A14: Coordinates and accessibility are tiered separately. | B14: A building can have a CONFIRMED coordinate and an UNKNOWN entrance. Buildings.display_tier refers only to the coordinate.
A16: METADATA (the metadata.json equivalent)
A17: coordinate_reference_system | B17: EPSG:4326 (WGS 84), decimal degrees; lon/lat order when exported to GeoJSON
A18: linear_units | B18: metres
A19: vertical_datum | B19: none - floor levels are ordinal labels (00 = basement), not elevations
A20: dataset_version | B20: 0.3.0-scaffold
A21: generated | B21: 2026-09-19
A22: last_field_verified | B22: NEVER - no field verification has taken place
A23: license | B23: Mixed / unresolved. See Sources. The uploaded floorplan mirror has no established licence.
A24: coverage | B24: 16 buildings, 32 entrances, 54 outdoor segments + 10 indoor traversals, 19 connectors, 8 POIs
A26: WHAT CHANGED IN v0.2
A27: 5 buildings added that postdate the 2006 archive. | B27: Data and Decision Sciences (2023), Kelly Hall (2008), Center for the Arts (2011), Hitt Hall (2024), Mitchell Hall (2028, under construction).
A28: Coordinates re-sourced against the 2025 campus map. | B28: 13 of 14 buildings now carry VT's own published coordinate. Only Hitt Hall is interpolated.
A29: display_tier added to four tabs. | B29: Buildings, Entrances, Paths, Elevators-Ramps-Stairs.
A30: Field Survey tab added. | B30: A walk order and a fill-in sheet that produces field_verified rows.
A31: Floorplan Gaps rebuilt against the 2025 map. | B31: Plus a rename/renumber warning list - see below.
A33: THE BLUEPRINT ANSWER
A34: There is no public source for VT floorplans. | B34: The 2006 CDCD mirror in your upload was a one-off scrape; the original site is gone. Current plans go through vtspacemgmt@vt.edu and are not published.
A35: Blueprints would not solve your problem anyway. | B35: A floorplan shows you a door. It does not tell you whether that door has a step, a 1:12 ramp, or a 40 mm lip. Step-free status is a survey attribute, not a drawing attribute.
A36: VT already has the data you actually want. | B36: The official interactive campus map already does accessible-only routing, with accessible entrances, elevators and curb cuts as layers. See Sources SRC-07.
A38: FIVE THINGS THAT NEED YOUR DECISION
A39: 1. Tab name changed. | B39: Excel forbids '/' in sheet names, so 'Elevators/Ramps/Stairs' is 'Elevators-Ramps-Stairs'.
A40: 2. connector_type has no bridge. | B40: Torgersen floor 2 connects to Newman Library floor 3 by enclosed bridge; Whittemore has 3rd-floor patio bridges. Three rows are parked under 'lift'. Add: bridge, tunnel, escalator.
A41: 3. status.csv's status column is ambiguous. | B41: Your example uses 'closed' (operational). A report about a step-free door needs an accessibility value. One column cannot carry both vocabularies.
A42: 4. No Nodes table. | B42: node_id is referenced by three tabs and defined in none. Junction coordinates are duplicated across path rows and will drift.
A43: 5. Building number is NOT a stable key. | B43: VT reuses numbers across demolition and rebuild. #188 was Shultz Hall in 2006 and is the Center for the Arts now - the archive's 0188 plans are the WRONG BUILDING. See Floorplan Gaps.
A45: LIVE COUNTS
A46: Buildings | B46: =COUNTA(Buildings!A2:A200)
A47: Entrances | B47: =COUNTA(Entrances!A2:A400)
...

Sheet Buildings
A1: building_id | B1: name | C1: building_number | D1: abbreviation | E1: latitude | F1: longitude | G1: address | H1: map_grid_2025 | I1: year_built | J1: geometry_type | K1: coord_source | L1: confidence | M1: floorplan_in_archive | N1: floorplan_files | O1: new_since_2006 | P1: display_tier | Q1: notes
A2: VT-GOODWIN | B2: Goodwin Hall | C2: 136 | D2: GOODW | E2: 37.23237 | F2: -80.42542 | G2: 635 Prices Fork Road | H2: G-2 | I2: 2014 | J2: point_centroid | K2: vt.edu/about/locations/buildings/signature-engineering.html | L2: official | M2: NO | O2: yes | P2: =IF(OR(L2="official",L2="field_verified"),"CONFIRMED","UNKNOWN") | Q2: Postdates the 2006 archive.
A3: VT-DURHAM | B3: Durham Hall | C3: 126 | D3: DURHM | E3: 37.23174 | F3: -80.42382 | G3: 1145 Perry St. | H3: G-2 | I3: 1997 | J3: point_centroid | K3: vt.edu/about/locations/buildings/durham-hall.html | L3: official | M3: yes | N3: 0126sa01.gif, 0126sa02.gif, 0126sa03.gif, 0126sa04.gif | O3: no | P3: =IF(OR(L3="official",L3="field_verified"),"CONFIRMED","UNKNOWN")
A4: VT-WHITTEMORE | B4: Whittemore Hall | C4: 134 | D4: WHIT | E4: 37.23107 | F4: -80.42445 | G4: 1185 Perry St. | H4: G-3 | I4: 1971 | J4: point_centroid | K4: vt.edu/about/locations/buildings/whittemore-hall.html | L4: official | M4: yes | N4: 0134sa01.gif, 0134sa02.gif, 0134sa03.gif, 0134sa04.gif, 0134sa05.gif, 0134sa06.gif, 0134sa14.gif | O4: no | P4: =IF(OR(L4="official",L4="field_verified"),"CONFIRMED","UNKNOWN")
A5: VT-MCBRYDE | B5: McBryde Hall | C5: 151 | D5: MCB | E5: 37.23062 | F5: -80.42178 | G5: 225 Stanger St. | H5: H-3 | I5: 1972 | J5: point_centroid | K5: vt.edu/about/locations/buildings/mcbryde-hall.html | L5: official | M5: yes | N5: 0151sa01.gif, 0151sa02.gif, 0151sa03.gif, 0151sa04.gif, 0151sa05.gif, 0151sa06.gif, 0151sa14.gif | O5: no | P5: =IF(OR(L5="official",L5="field_verified"),"CONFIRMED","UNKNOWN")
A6: VT-HANCOCK | B6: John W. Hancock Jr. Hall | C6: 133C | D6: HAN | E6: 37.23016 | F6: -80.42427 | G6: 490 Old Turner St. | H6: G-3 | I6: 1990 | J6: point_centroid | K6: vt.edu/about/locations/buildings/hancock-hall.html | L6: official | M6: yes | N6: 133csa00.gif, 133csa01.gif, 133csa02.gif | O6: no | P6: =IF(OR(L6="official",L6="field_verified"),"CONFIRMED","UNKNOWN")
A7: VT-TORGERSEN | B7: Torgersen Hall | C7: 174 | D7: TORG | E7: 37.22978 | F7: -80.41997 | G7: 620 Drillfield Drive | H7: I-3 | I7: 2000 | J7: point_centroid | K7: vt.edu/about/locations/buildings/torgersen-hall.html | L7: official | M7: yes | N7: 0174sa01.gif, 0174sa02.gif, 0174sa03.gif, 0174sa17.gif | O7: no | P7: =IF(OR(L7="official",L7="field_verified"),"CONFIRMED","UNKNOWN")
A8: VT-SQUIRES | B8: Squires Student Center | C8: 180 | D8: SQUIR | E8: 37.22962 | F8: -80.41796 | G8: 290 College Ave. | H8: I-3 | I8: 1937 | J8: point_centroid | K8: vt.edu/about/locations/buildings/squires-student-center.html | L8: official | M8: yes | N8: 0180sa00.gif, 0180sa01.gif, 0180sa02.gif, 0180sa03.gif, 0180sa04.gif | O8: no | P8: =IF(OR(L8="official",L8="field_verified"),"CONFIRMED","UNKNOWN")
A9: VT-BURRUSS | B9: Burruss Hall | C9: 176 | D9: BUR | E9: 37.229 | F9: -80.42371 | G9: 800 Drillfield Drive | H9: G-4 | I9: 1936 | J9: point_centroid | K9: vt.edu/about/locations/buildings/burruss-hall.html | L9: official | M9: yes | N9: 0176sa01.gif, 0176sa02.gif, 0176sa03.gif, 0176sa04.gif, 0176sa05.gif, 0176sa06.gif | O9: no | P9: =IF(OR(L9="official",L9="field_verified"),"CONFIRMED","UNKNOWN")
A10: VT-NEWMAN-LIB | B10: Carol M. Newman Library | C10: 177 | D10: LIBR | E10: 37.22876 | F10: -80.41924 | G10: 560 Drillfield Drive | H10: I-4 | I10: 1955 | J10: point_centroid | K10: vt.edu/about/locations/buildings/newman-library.html | L10: official | M10: NO | O10: no | P10: =IF(OR(L10="official",L10="field_verified"),"CONFIRMED","UNKNOWN") | Q10: Listed in the 2006 index but no plan file was mirrored.
A11: VT-DDS | B11: Data and Decision Sciences Building | C11: 137 | D11: DDS | E11: 37.23186 | F11: -80.42694 | G11: 727 Prices Fork Road | H11: F-2 | I11: 2023 | J11: point_centroid | K11: vt.edu/about/locations/buildings/data-and-decision-sciences.html | L11: official | M11: NO | O11: yes | P11: =IF(OR(L11="official",L11="field_verified"),"CONFIRMED","UNKNOWN") | Q11: Postdates the 2006 archive.
A12: VT-KELLY | B12: Kelly Hall | C12: 129 | D12: KELLY | E12: 37.23108 | F12: -80.42244 | G12: 325 Stanger St. | H12: H-3 | I12: 2008 | J12: point_centroid | K12: vt.edu/about/locations/buildings/kelly-hall.html | L12: official | M12: NO | O12: yes | P12: =IF(OR(L12="official",L12="field_verified"),"CONFIRMED","UNKNOWN") | Q12: Postdates the 2006 archive.
A13: VT-CFA | B13: Center for the Arts (formerly Moss Arts Center) | C13: 188 | D13: MAC | E13: 37.23234 | F13: -80.41765 | G13: 190 Alumni Mall | H13: I-2 | I13: 2011 | J13: point_centroid | K13: vt.edu/about/locations/buildings/center-for-the-arts.html | L13: official | M13: yes | N13: 0188sa00.gif, 0188sa15.gif | O13: yes | P13: =IF(OR(L13="official",L13="field_verified"),"CONFIRMED","UNKNOWN")
A14: VT-HITT | B14: Hitt Hall | C14: 168 | D14: HITT | E14: 37.2314 | F14: -80.4276 | G14: 1385 Perry St. | H14: G-3 | I14: 2024 | J14: point_centroid | K14: Perry St address interpolation between Whittemore (1185) and Bishop-Favrao (1345); grid G-3 on the 2025 map | L14: inferred | M14: NO | O14: yes | P14: =IF(OR(L14="official",L14="field_verified"),"CONFIRMED","UNKNOWN") | Q14: Postdates the 2006 archive.
A15: VT-MITCHELL | B15: Mitchell Hall (under construction, 2028) | C15: 133 | D15: MITCH | E15: 37.2311 | F15: -80.4234 | G15: Randolph Hall site, Stanger St. | H15: H-3 | I15: 2028 | J15: point_centroid | K15: Placed on the former Randolph Hall footprint between Whittemore and Kelly. NOT a surveyed position. | L15: inferred | M15: NO | O15: yes | P15: =IF(OR(L15="official",L15="field_verified"),"CONFIRMED","UNKNOWN") | Q15: Postdates the 2006 archive.
A16: VT-DERRING | B16: Derring Hall | C16: 155 | D16: DER | E16: 37.22908 | F16: -80.4256 | G16: 926 West Campus Drive | H16: G-3 | I16: 1969 | J16: point_centroid | K16: vt.edu/about/locations/buildings/derring-hall.html | L16: official | M16: NO | O16: no | P16: =IF(OR(L16="official",L16="field_verified"),"CONFIRMED","UNKNOWN") | Q16: Listed in the 2006 index but no plan file was mirrored.
A17: VT-PAMPLIN | B17: Pamplin Hall | C17: 153 | D17: PAM | E17: 37.22876 | F17: -80.42462 | G17: 880 West Campus Drive | H17: G-4 | I17: 1957 | J17: point_centroid | K17: vt.edu/about/locations/buildings/pamplin-hall.html | L17: official | M17: yes | N17: 0153sa00.gif, 0153sa01.gif, 0153sa02.gif, 0153sa03.gif, 0153sa16.gif | O17: no | P17: =IF(OR(L17="official",L17="field_verified"),"CONFIRMED","UNKNOWN")

Sheet Entrances
A1: entrance_id | B1: building_id | C1: node_id | D1: entrance_name | E1: latitude | F1: longitude | G1: accessibility_status | H1: operational_status | I1: door_type | J1: step_count | K1: geometry_precision | L1: confidence | M1: last_verified | N1: display_tier | O1: notes
A2: VT-GOODWIN-E1 | B2: VT-GOODWIN | C2: N-GOODWIN-E1 | D2: Perry Street side | E2: 37.232015 | F2: -80.425258 | G2: unknown | H2: unknown | I2: unknown | K2: placeholder_offset_from_centroid | L2: inferred | N2: =IF(OR(L2="official",L2="field_verified"),"CONFIRMED","UNKNOWN") | O2: Not surveyed.
A3: VT-GOODWIN-E2 | B3: VT-GOODWIN | C3: N-GOODWIN-E2 | D3: East side / plaza | E3: 37.23237 | F3: -80.424912 | G3: unknown | H3: unknown | I3: unknown | K3: placeholder_offset_from_centroid | L3: inferred | N3: =IF(OR(L3="official",L3="field_verified"),"CONFIRMED","UNKNOWN") | O3: Not surveyed.
A4: VT-DURHAM-E1 | B4: VT-DURHAM | C4: N-DURHAM-E1 | D4: Perry Street side | E4: 37.231629 | F4: -80.424202 | G4: unknown | H4: unknown | I4: unknown | K4: placeholder_offset_from_centroid | L4: inferred | N4: =IF(OR(L4="official",L4="field_verified"),"CONFIRMED","UNKNOWN") | O4: Not surveyed.
A5: VT-DURHAM-E2 | B5: VT-DURHAM | C5: N-DURHAM-E2 | D5: South side toward Stanger | E5: 37.231416 | F5: -80.42382 | G5: unknown | H5: unknown | I5: unknown | K5: placeholder_offset_from_centroid | L5: inferred | N5: =IF(OR(L5="official",L5="field_verified"),"CONFIRMED","UNKNOWN") | O5: Not surveyed.
A6: VT-WHITTEMORE-E1 | B6: VT-WHITTEMORE | C6: N-WHITTEMORE-E1 | D6: North side / Perry Street | E6: 37.231374 | F6: -80.424311 | G6: unknown | H6: unknown | I6: unknown | K6: placeholder_offset_from_centroid | L6: inferred | N6: =IF(OR(L6="official",L6="field_verified"),"CONFIRMED","UNKNOWN") | O6: Not surveyed.
A7: VT-WHITTEMORE-E2 | B7: VT-WHITTEMORE | C7: N-WHITTEMORE-E2 | D7: South side toward Hancock | E7: 37.230747 | F7: -80.424415 | G7: unknown | H7: unknown | I7: unknown | K7: placeholder_offset_from_centroid | L7: inferred | N7: =IF(OR(L7="official",L7="field_verified"),"CONFIRMED","UNKNOWN") | O7: Not surveyed.
A8: VT-MCBRYDE-EN | B8: VT-MCBRYDE | C8: N-MCBRYDE-EN | D8: North entrance | E8: 37.23098 | F8: -80.42178 | G8: unknown | H8: unknown | I8: unknown | K8: placeholder_offset_from_centroid | L8: inferred | N8: =IF(OR(L8="official",L8="field_verified"),"CONFIRMED","UNKNOWN") | O8: VT states McBryde's entrances face due N/S/E/W.
A9: VT-MCBRYDE-ES | B9: VT-MCBRYDE | C9: N-MCBRYDE-ES | D9: South entrance | E9: 37.23026 | F9: -80.42178 | G9: unknown | H9: unknown | I9: unknown | K9: placeholder_offset_from_centroid | L9: inferred | N9: =IF(OR(L9="official",L9="field_verified"),"CONFIRMED","UNKNOWN") | O9: VT states McBryde's entrances face due N/S/E/W.
A10: VT-MCBRYDE-EW | B10: VT-MCBRYDE | C10: N-MCBRYDE-EW | D10: West entrance | E10: 37.23062 | F10: -80.422232 | G10: unknown | H10: unknown | I10: unknown | K10: placeholder_offset_from_centroid | L10: inferred | N10: =IF(OR(L10="official",L10="field_verified"),"CONFIRMED","UNKNOWN") | O10: VT states McBryde's entrances face due N/S/E/W.
A11: VT-HANCOCK-E1 | B11: VT-HANCOCK | C11: N-HANCOCK-E1 | D11: Old Turner Street side | E11: 37.230135 | F11: -80.42463 | G11: unknown | H11: unknown | I11: unknown | K11: placeholder_offset_from_centroid | L11: inferred | N11: =IF(OR(L11="official",L11="field_verified"),"CONFIRMED","UNKNOWN") | O11: Not surveyed.
A12: VT-HANCOCK-E2 | B12: VT-HANCOCK | C12: N-HANCOCK-E2 | D12: East side toward Drillfield | E12: 37.230185 | F12: -80.42391 | G12: unknown | H12: unknown | I12: unknown | K12: placeholder_offset_from_centroid | L12: inferred | N12: =IF(OR(L12="official",L12="field_verified"),"CONFIRMED","UNKNOWN") | O12: Not surveyed.
A13: VT-TORGERSEN-E1 | B13: VT-TORGERSEN | C13: N-TORGERSEN-E1 | D13: Alumni Mall / south side | E13: 37.229456 | F13: -80.41997 | G13: unknown | H13: unknown | I13: unknown | K13: placeholder_offset_from_centroid | L13: inferred | N13: =IF(OR(L13="official",L13="field_verified"),"CONFIRMED","UNKNOWN") | O13: Not surveyed.
... A33: VT-PAMPLIN-EN | B33: VT-PAMPLIN | C33: N-PAMPLIN-EN | D33: North side / atrium | E33: 37.229115 | F33: -80.424458 | G33: unknown | H33: unknown | I33: unknown | K33: placeholder_offset_from_centroid | L33: inferred | N33: =IF(OR(L33="official",L33="field_verified"),"CONFIRMED","UNKNOWN") | O33: 1988 atrium links the old and new wings. NOT surveyed.

Sheet Paths
A1: segment_id | B1: from_node | C1: to_node | D1: from_lat | E1: from_lon | F1: to_lat | G1: to_lon | H1: length_m | I1: accessibility_status | J1: operational_status | K1: surface | L1: max_grade_pct | M1: width_m | N1: is_indoor | O1: open_hours | P1: access_control | Q1: confidence | R1: last_verified | S1: display_tier | T1: notes
A2: SEG-001 | B2: N-GOODWIN-E1 | C2: J-PERRY-W | D2: 37.232015 | E2: -80.425258 | F2: 37.232055 | G2: -80.42462 | H2: =ROUND(6371000*2*ASIN(SQRT(SIN(RADIANS(F2-D2)/2)^2+COS(RADIANS(D2))*COS(RADIANS(F2))*SIN(RADIANS(G2-E2)/2)^2)),1) | I2: unknown | J2: unknown | K2: unknown | N2: no | P2: outdoor | Q2: inferred | S2: =IF(OR(Q2="official",Q2="field_verified"),"CONFIRMED","UNKNOWN") | T2: Perry Street frontage. Not surveyed.
A3: SEG-002 | B3: J-PERRY-W | C3: N-DURHAM-E1 | D3: 37.232055 | E3: -80.42462 | F3: 37.231629 | G3: -80.424202 | H3: =ROUND(6371000*2*ASIN(SQRT(SIN(RADIANS(F3-D3)/2)^2+COS(RADIANS(D3))*COS(RADIANS(F3))*SIN(RADIANS(G3-E3)/2)^2)),1) | I3: unknown | J3: unknown | K3: unknown | N3: no | P3: outdoor | Q3: inferred | S3: =IF(OR(Q3="official",Q3="field_verified"),"CONFIRMED","UNKNOWN") | T3: Not surveyed.
A4: SEG-003 | B4: N-DURHAM-E2 | C4: J-PERRY-E | D4: 37.231416 | E4: -80.42382 | F4: 37.231405 | G4: -80.424135 | H4: =ROUND(6371000*2*ASIN(SQRT(SIN(RADIANS(F4-D4)/2)^2+COS(RADIANS(D4))*COS(RADIANS(F4))*SIN(RADIANS(G4-E4)/2)^2)),1) | I4: unknown | J4: unknown | K4: unknown | N4: no | P4: outdoor | Q4: inferred | S4: =IF(OR(Q4="official",Q4="field_verified"),"CONFIRMED","UNKNOWN") | T4: Not surveyed.
A5: SEG-004 | B5: J-PERRY-E | C5: N-WHITTEMORE-E1 | D5: 37.231405 | E5: -80.424135 | F5: 37.231374 | G5: -80.424311 | H5: =ROUND(6371000*2*ASIN(SQRT(SIN(RADIANS(F5-D5)/2)^2+COS(RADIANS(D5))*COS(RADIANS(F5))*SIN(RADIANS(G5-E5)/2)^2)),1) | I5: unknown | J5: unknown | K5: unknown | N5: no | P5: outdoor | Q5: inferred | S5: =IF(OR(Q5="official",Q5="field_verified"),"CONFIRMED","UNKNOWN") | T5: Not surveyed.
A6: SEG-005 | B6: N-WHITTEMORE-E2 | C6: J-WHIT-S | D6: 37.230747 | E6: -80.424415 | F6: 37.230615 | G6: -80.42436 | H6: =ROUND(6371000*2*ASIN(SQRT(SIN(RADIANS(F6-D6)/2)^2+COS(RADIANS(D6))*COS(RADIANS(F6))*SIN(RADIANS(G6-E6)/2)^2)),1) | I6: unknown | J6: unknown | K6: unknown | N6: no | P6: outdoor | Q6: inferred | S6: =IF(OR(Q6="official",Q6="field_verified"),"CONFIRMED","UNKNOWN") | T6: Not surveyed.
A7: SEG-006 | B7: J-WHIT-S | C7: N-HANCOCK-E2 | D7: 37.230615 | E7: -80.42436 | F7: 37.230185 | G7: -80.42391 | H7: =ROUND(6371000*2*ASIN(SQRT(SIN(RADIANS(F7-D7)/2)^2+COS(RADIANS(D7))*COS(RADIANS(F7))*SIN(RADIANS(G7-E7)/2)^2)),1) | I7: unknown | J7: unknown | K7: unknown | N7: no | P7: outdoor | Q7: inferred | S7: =IF(OR(Q7="official",Q7="field_verified"),"CONFIRMED","UNKNOWN") | T7: Not surveyed.
A8: SEG-007 | B8: N-HANCOCK-E1 | C8: J-DF-NW | D8: 37.230135 | E8: -80.42463 | F8: 37.229325 | G8: -80.423867 | H8: =ROUND(6371000*2*ASIN(SQRT(SIN(RADIANS(F8-D8)/2)^2+COS(RADIANS(D8))*COS(RADIANS(F8))*SIN(RADIANS(G8-E8)/2)^2)),1) | I8: unknown | J8: unknown | K8: unknown | N8: no | P8: outdoor | Q8: inferred | S8: =IF(OR(Q8="official",Q8="field_verified"),"CONFIRMED","UNKNOWN") | T8: Old Turner Street toward the Drillfield. Not surveyed.
A9: SEG-008 | B9: J-DF-NW | C9: N-BURRUSS-E2 | D9: 37.229325 | E9: -80.423867 | F9: 37.229354 | G9: -80.423632 | H9: =ROUND(6371000*2*ASIN(SQRT(SIN(RADIANS(F9-D9)/2)^2+COS(RADIANS(D9))*COS(RADIANS(F9))*SIN(RADIANS(G9-E9)/2)^2)),1) | I9: unknown | J9: unknown | K9: unknown | N9: no | P9: outdoor | Q9: inferred | S9: =IF(OR(Q9="official",Q9="field_verified"),"CONFIRMED","UNKNOWN") | T9: Not surveyed.
A10: SEG-009 | B10: N-BURRUSS-E1 | C10: J-DF-N | D10: 37.228928 | E10: -80.423198 | F10: 37.22888 | G10: -80.421475 | H10: =ROUND(6371000*2*ASIN(SQRT(SIN(RADIANS(F10-D10)/2)^2+COS(RADIANS(D10))*COS(RADIANS(F10))*SIN(RADIANS(G10-E10)/2)^2)),1) | I10: stairs | J10: unknown | K10: unknown | N10: no | P10: outdoor | Q10: inferred | S10: =IF(OR(Q10="official",Q10="field_verified"),"CONFIRMED","UNKNOWN") | T10: Drillfield front of Burruss: stepped approach. Step count and grade NOT measured.
A11: SEG-010 | B11: J-DF-N | C11: J-DF-E | D11: 37.22888 | E11: -80.421475 | F11: 37.228796 | G11: -80.419911 | H11: =ROUND(6371000*2*ASIN(SQRT(SIN(RADIANS(F11-D11)/2)^2+COS(RADIANS(D11))*COS(RADIANS(F11))*SIN(RADIANS(G11-E11)/2)^2)),1) | I11: unknown | J11: unknown | K11: paved | N11: no | P11: outdoor | Q11: inferred | S11: =IF(OR(Q11="official",Q11="field_verified"),"CONFIRMED","UNKNOWN") | T11: Drillfield perimeter walk. Paved, grade NOT measured.
A12: SEG-011 | B12: J-DF-E | C12: N-NEWMAN-LIB-E1 | D12: 37.228796 | E12: -80.419911 | F12: 37.228704 | G12: -80.41964 | H12: =ROUND(6371000*2*ASIN(SQRT(SIN(RADIANS(F12-D12)/2)^2+COS(RADIANS(D12))*COS(RADIANS(F12))*SIN(RADIANS(G12-E12)/2)^2)),1) | I12: unknown | J12: unknown | K12: unknown | N12: no | P12: outdoor | Q12: inferred | S12: =IF(OR(Q12="official",Q12="field_verified"),"CONFIRMED","UNKNOWN") | T12: Not surveyed.
A13: SEG-012 | B13: N-NEWMAN-LIB-E2 | C13: J-ALUMNI-W | D13: 37.229079 | E13: -80.419169 | F13: 37.229219 | G13: -80.419568 | H13: =ROUND(6371000*2*ASIN(SQRT(SIN(RADIANS(F13-D13)/2)^2+COS(RADIANS(D13))*COS(RADIANS(F13))*SIN(RADIANS(G13-E13)/2)^2)),1) | I13: unknown | J13: unknown | K13: paved | N13: no | P13: outdoor | Q13: inferred | S13: =IF(OR(Q13="official",Q13="field_verified"),"CONFIRMED","UNKNOWN") | T13: Alumni Mall west end. Not surveyed.
... A55: SEG-040 | B55: J-DERRING-SW | C55: N-HANCOCK-E1 | D55: 37.228432 | E55: -80.42617 | F55: 37.230135 | G55: -80.42463 | H55: =ROUND(6371000*2*ASIN(SQRT(SIN(RADIANS(F55-D55)/2)^2+COS(RADIANS(D55))*COS(RADIANS(F55))*SIN(RADIANS(G55-E55)/2)^2)),1) | I55: unknown | J55: unknown | K55: unknown | N55: no | P55: outdoor | Q55: inferred | S55: =IF(OR(Q55="official",Q55="field_verified"),"CONFIRMED","UNKNOWN") | T55: Derring toward Hancock. NOT surveyed.
A56: IND-DERRING-1 | B56: N-DERRING-EN | C56: N-DERRING-EE | D56: 37.22946 | E56: -80.425774 | F56: 37.229041 | G56: -80.425037 | H56: =ROUND(6371000*2*ASIN(SQRT(SIN(RADIANS(F56-D56)/2)^2+COS(RADIANS(D56))*COS(RADIANS(F56))*SIN(RADIANS(G56-E56)/2)^2)),1) | I56: unknown | J56: unknown | K56: indoor | N56: yes | O56: unknown | P56: unknown | Q56: inferred | S56: =IF(OR(Q56="official",Q56="field_verified"),"CONFIRMED","UNKNOWN") | T56: THE DEMO EDGE. Cut through Derring north-to-east instead of walking the corner. Derring is 208,000 sq ft, VT's largest undergraduate science lab building, so the corner walk is long. Interior route, hours and swipe policy are ALL unverified.
A57: IND-HITT-1 | B57: N-HITT-E1 | C57: N-HITT-E2 | D57: 37.231046 | E57: -80.427678 | F57: 37.231462 | G57: -80.427155 | H57: =ROUND(6371000*2*ASIN(SQRT(SIN(RADIANS(F57-D57)/2)^2+COS(RADIANS(D57))*COS(RADIANS(F57))*SIN(RADIANS(G57-E57)/2)^2)),1) | I57: unknown | J57: unknown | K57: indoor | N57: yes | O57: unknown | P57: unknown | Q57: inferred | S57: =IF(OR(Q57="official",Q57="field_verified"),"CONFIRMED","UNKNOWN") | T57: Through Hitt Hall past Perry Place. Dining hall hours will differ from building hours - do not assume they match.
A58: IND-TORG-1 | B58: N-TORGERSEN-E1 | C58: N-TORGERSEN-E2 | D58: 37.229456 | E58: -80.41997 | F58: 37.230104 | G58: -80.41997 | H58: =ROUND(6371000*2*ASIN(SQRT(SIN(RADIANS(F58-D58)/2)^2+COS(RADIANS(D58))*COS(RADIANS(F58))*SIN(RADIANS(G58-E58)/2)^2)),1) | I58: unknown | J58: unknown | K58: indoor | N58: yes | O58: unknown | P58: unknown | Q58: inferred | S58: =IF(OR(Q58="official",Q58="field_verified"),"CONFIRMED","UNKNOWN") | T58: Through Torgersen Hall.
A59: IND-TORG-NEWMAN | B59: N-TORGERSEN-E1 | C59: N-NEWMAN-LIB-E2 | D59: 37.229456 | E59: -80.41997 | F59: 37.229079 | G59: -80.419169 | H59: =ROUND(6371000*2*ASIN(SQRT(SIN(RADIANS(F59-D59)/2)^2+COS(RADIANS(D59))*COS(RADIANS(F59))*SIN(RADIANS(G59-E59)/2)^2)),1) | I59: unknown | J59: unknown | K59: indoor | N59: yes | O59: unknown | P59: unknown | Q59: inferred | S59: =IF(OR(Q59="official",Q59="field_verified"),"CONFIRMED","UNKNOWN") | T59: Through Torgersen and over the enclosed bridge into Newman Library. Crosses TWO buildings and changes floor (Torgersen 2 -> Newman 3), so it depends on connector VT-TORG-NEWMAN-BRIDGE and on a working lift at each end.
A60: IND-SQUIRES-1 | B60: N-SQUIRES-E1 | C60: N-SQUIRES-E2 | D60: 37.22962 | E60: -80.41848 | F60: 37.22998 | G60: -80.41796 | H60: =ROUND(6371000*2*ASIN(SQRT(SIN(RADIANS(F60-D60)/2)^2+COS(RADIANS(D60))*COS(RADIANS(F60))*SIN(RADIANS(G60-E60)/2)^2)),1) | I60: unknown | J60: unknown | K60: indoor | N60: yes | O60: unknown | P60: unknown | Q60: inferred | S60: =IF(OR(Q60="official",Q60="field_verified"),"CONFIRMED","UNKNOWN") | T60: Through Squires between Alumni Mall and College Avenue.
A61: IND-MCBRYDE-1 | B61: N-MCBRYDE-EN | C61: N-MCBRYDE-ES | D61: 37.23098 | E61: -80.42178 | F61: 37.23026 | G61: -80.42178 | H61: =ROUND(6371000*2*ASIN(SQRT(SIN(RADIANS(F61-D61)/2)^2+COS(RADIANS(D61))*COS(RADIANS(F61))*SIN(RADIANS(G61-E61)/2)^2)),1) | I61: unknown | J61: unknown | K61: indoor | N61: yes | O61: unknown | P61: unknown | Q61: inferred | S61: =IF(OR(Q61="official",Q61="field_verified"),"CONFIRMED","UNKNOWN") | T61: Through McBryde north to south.
A62: IND-MCBRYDE-2 | B62: N-MCBRYDE-EW | C62: N-MCBRYDE-ES | D62: 37.23062 | E62: -80.422232 | F62: 37.23026 | G62: -80.42178 | H62: =ROUND(6371000*2*ASIN(SQRT(SIN(RADIANS(F62-D62)/2)^2+COS(RADIANS(D62))*COS(RADIANS(F62))*SIN(RADIANS(G62-E62)/2)^2)),1) | I62: unknown | J62: unknown | K62: indoor | N62: yes | O62: unknown | P62: unknown | Q62: inferred | S62: =IF(OR(Q62="official",Q62="field_verified"),"CONFIRMED","UNKNOWN") | T62: Through McBryde west to south.
A63: IND-BURRUSS-1 | B63: N-BURRUSS-E1 | C63: N-BURRUSS-E2 | D63: 37.228928 | E63: -80.423198 | F63: 37.229354 | G63: -80.423632 | H63: =ROUND(6371000*2*ASIN(SQRT(SIN(RADIANS(F63-D63)/2)^2+COS(RADIANS(D63))*COS(RADIANS(F63))*SIN(RADIANS(G63-E63)/2)^2)),1) | I63: unknown | J63: unknown | K63: indoor | N63: yes | O63: unknown | P63: unknown | Q63: inferred | S63: =IF(OR(Q63="official",Q63="field_verified"),"CONFIRMED","UNKNOWN") | T63: Through Burruss. The Drillfield door is stepped, so this only helps if the north door is step-free.
A64: IND-PAMPLIN-1 | B64: N-PAMPLIN-EW | C64: N-PAMPLIN-EN | D64: 37.228727 | E64: -80.425093 | F64: 37.229115 | G64: -80.424458 | H64: =ROUND(6371000*2*ASIN(SQRT(SIN(RADIANS(F64-D64)/2)^2+COS(RADIANS(D64))*COS(RADIANS(F64))*SIN(RADIANS(G64-E64)/2)^2)),1) | I64: unknown | J64: unknown | K64: indoor | N64: yes | O64: unknown | P64: unknown | Q64: inferred | S64: =IF(OR(Q64="official",Q64="field_verified"),"CONFIRMED","UNKNOWN") | T64: Through the Pamplin atrium, which links the 1957 and 1988 wings.
A65: IND-WHIT-DURHAM | B65: N-WHITTEMORE-E1 | C65: N-DURHAM-E2 | D65: 37.231374 | E65: -80.424311 | F65: 37.231416 | G65: -80.42382 | H65: =ROUND(6371000*2*ASIN(SQRT(SIN(RADIANS(F65-D65)/2)^2+COS(RADIANS(D65))*COS(RADIANS(F65))*SIN(RADIANS(G65-E65)/2)^2)),1) | I65: unknown | J65: unknown | K65: indoor | N65: yes | O65: unknown | P65: unknown | Q65: inferred | S65: =IF(OR(Q65="official",Q65="field_verified"),"CONFIRMED","UNKNOWN") | T65: Whittemore to Durham via the 3rd-floor bridge. Needs a working lift in both buildings.

Sheet Elevators-Ramps-Stairs
A1: connector_id | B1: building_id | C1: from_node | D1: to_node | E1: connector_type | F1: floors_served | G1: accessibility_status | H1: operational_status | I1: confidence | J1: evidence_source | K1: last_verified | L1: display_tier | M1: notes
A2: VT-BURRUSS-ELEV-1 | B2: VT-BURRUSS | C2: N-BURRUSS-L1 | D2: N-BURRUSS-L6 | E2: elevator | F2: 01-06 | G2: step_free | H2: unknown | I2: inferred | J2: CDCD floorplan 0176sa02.gif (2006) | L2: =IF(OR(I2="official",I2="field_verified"),"CONFIRMED","UNKNOWN") | M2: Car labelled ELEV. off the main foyer. Existence in 2026 NOT confirmed; cab and door dimensions unknown.
A3: VT-BURRUSS-STAIR-200A | B3: VT-BURRUSS | C3: N-BURRUSS-L1 | D3: N-BURRUSS-L2 | E3: stairs | F3: 01-02 | G3: stairs | H3: unknown | I3: inferred | J3: CDCD floorplan 0176sa02.gif (2006) | L3: =IF(OR(I3="official",I3="field_verified"),"CONFIRMED","UNKNOWN") | M3: Labelled STAIR 200A.
A4: VT-BURRUSS-STAIR-200B | B4: VT-BURRUSS | C4: N-BURRUSS-L1 | D4: N-BURRUSS-L2 | E4: stairs | F4: 01-02 | G4: stairs | H4: unknown | I4: inferred | J4: CDCD floorplan 0176sa02.gif (2006) | L4: =IF(OR(I4="official",I4="field_verified"),"CONFIRMED","UNKNOWN") | M4: Labelled STAIR 200B.
A5: VT-TORG-ELEV-B3 | B5: VT-TORGERSEN | C5: N-TORGERSEN-L1 | D5: N-TORGERSEN-L3 | E5: elevator | F5: 01-03 | G5: step_free | H5: unknown | I5: inferred | J5: CDCD floorplan 0174sa02.gif (2006) | L5: =IF(OR(I5="official",I5="field_verified"),"CONFIRMED","UNKNOWN") | M5: Labelled ELEV. B3, west end.
A6: VT-TORG-ELEV-B15 | B6: VT-TORGERSEN | C6: N-TORGERSEN-L1 | D6: N-TORGERSEN-L3 | E6: elevator | F6: 01-03 | G6: step_free | H6: unknown | I6: inferred | J6: CDCD floorplan 0174sa02.gif (2006) | L6: =IF(OR(I6="official",I6="field_verified"),"CONFIRMED","UNKNOWN") | M6: Labelled ELEV. B15, centre.
A7: VT-TORG-NEWMAN-BRIDGE | B7: VT-TORGERSEN | C7: N-TORGERSEN-L2 | D7: N-NEWMAN-LIB-L3 | E7: lift | F7: T02-L03 | G7: unknown | H7: unknown | I7: inferred | J7: CDCD floorplan 0174sa02.gif (2006) | L7: =IF(OR(I7="official",I7="field_verified"),"CONFIRMED","UNKNOWN") | M7: ENCLOSED BRIDGE over Alumni Mall: Torgersen floor 2 to Newman Library floor 3. 'lift' is a MISFIT - connector_type has no bridge value. See README item 2.
A8: VT-WHIT-BRIDGE-DURHAM | B8: VT-WHITTEMORE | C8: N-WHITTEMORE-L3 | D8: N-DURHAM-L3 | E8: lift | F8: 03 | G8: unknown | H8: unknown | I8: community_report | J8: Gobblerpedia, Whittemore Hall | L8: =IF(OR(I8="official",I8="field_verified"),"CONFIRMED","UNKNOWN") | M8: 3rd-floor patio bridge to Durham. Same vocabulary gap.
A9: VT-WHIT-BRIDGE-HANCOCK | B9: VT-WHITTEMORE | C9: N-WHITTEMORE-L3 | D9: N-HANCOCK-L3 | E9: lift | F9: 03 | G9: unknown | H9: unknown | I9: community_report | J9: Gobblerpedia, Whittemore Hall | L9: =IF(OR(I9="official",I9="field_verified"),"CONFIRMED","UNKNOWN") | M9: 3rd-floor patio bridge to Hancock. Same vocabulary gap.
A10: VT-SQUIRES-ELEV-1 | B10: VT-SQUIRES | C10: N-SQUIRES-L1 | D10: N-SQUIRES-L4 | E10: elevator | F10: 00-04 | G10: step_free | H10: unknown | I10: inferred | J10: CDCD floorplan 0180sa01.gif (2006) | L10: =IF(OR(I10="official",I10="field_verified"),"CONFIRMED","UNKNOWN") | M10: Elevator and machine room visible on the 2006 plan.
A11: VT-SQUIRES-STAIR-A66 | B11: VT-SQUIRES | C11: N-SQUIRES-L1 | D11: N-SQUIRES-L2 | E11: stairs | F11: 01-02 | G11: stairs | H11: unknown | I11: inferred | J11: CDCD floorplan 0180sa01.gif (2006) | L11: =IF(OR(I11="official",I11="field_verified"),"CONFIRMED","UNKNOWN") | M11: Labelled STAIRS A66.
A12: VT-MCBRYDE-VERT-UNKNOWN | B12: VT-MCBRYDE | C12: N-MCBRYDE-L1 | D12: N-MCBRYDE-L6 | E12: unknown | F12: 01-06 | G12: unknown | H12: unknown | I12: inferred | J12: Not inspected | L12: =IF(OR(I12="official",I12="field_verified"),"CONFIRMED","UNKNOWN") | M12: Plans 0151sa01-06 exist in the archive but were NOT opened. Placeholder.
A13: VT-GOODWIN-VERT-UNKNOWN | B13: VT-GOODWIN | C13: N-GOODWIN-L1 | D13: N-GOODWIN-L6 | E13: unknown | F13: unknown | G13: unknown | H13: unknown | I13: inferred | J13: NO DATA | L13: =IF(OR(I13="official",I13="field_verified"),"CONFIRMED","UNKNOWN") | M13: Opened 2014. No floorplan anywhere public. Must be surveyed.
... A20: VT-MITCHELL-VERT-UNKNOWN | B20: VT-MITCHELL | C20: N-MITCHELL-L1 | D20: N-MITCHELL-L6 | E20: unknown | F20: unknown | G20: unknown | H20: unknown | I20: inferred | J20: NO DATA | L20: =IF(OR(I20="official",I20="field_verified"),"CONFIRMED","UNKNOWN") | M20: Building does not exist yet - completion 2028.

Sheet POIs
A1: poi_id | B1: name | C1: aliases | D1: building_id | E1: node_id | F1: floor | G1: category | H1: confidence | I1: display_tier | J1: notes
A2: POI-PERRY-PLACE | B2: Perry Place | C2: Perry Place Dining;Hitt dining;Perry Pl | D2: VT-HITT | E2: N-HITT-E1 | F2: 01-02 | G2: dining | H2: inferred | I2: =IF(OR(H2="official",H2="field_verified"),"CONFIRMED","UNKNOWN") | J2: 600-seat dining facility with nine venues, inside Hitt Hall. Entrance node is a PLACEHOLDER - no interior survey.
A3: POI-PROCON | B3: Procon Innovation Center | C3: Innovation Lab;Procon | D3: VT-HITT | E3: N-HITT-E1 | F3: 01-02 | G3: academic | H3: inferred | I3: =IF(OR(H3="official",H3="field_verified"),"CONFIRMED","UNKNOWN") | J3: Two-storey innovation centre inside Hitt Hall.
A4: POI-PAMPLIN-DEAN | B4: Pamplin College of Business - Dean's Office | C4: Pamplin dean;business school office | D4: VT-PAMPLIN | E4: N-PAMPLIN-EN | G4: office | H4: inferred | I4: =IF(OR(H4="official",H4="field_verified"),"CONFIRMED","UNKNOWN") | J4: Room number unknown. Mapped to the building's north entrance.
A5: POI-MUSEUM-GEO | B5: Museum of Geosciences | C5: Geosciences Museum;Derring museum | D5: VT-DERRING | E5: N-DERRING-EN | G5: attraction | H5: inferred | I5: =IF(OR(H5="official",H5="field_verified"),"CONFIRMED","UNKNOWN") | J5: Inside Derring Hall. Floor and room unknown.
A6: POI-NEWMAN-CAFE | B6: Newman Library cafe | C6: library coffee;Au Bon Pain | D6: VT-NEWMAN-LIB | E6: N-NEWMAN-LIB-E2 | F6: 01 | G6: dining | H6: inferred | I6: =IF(OR(H6="official",H6="field_verified"),"CONFIRMED","UNKNOWN") | J6: Lobby cafe added in the 2009 renovation.
A7: POI-BURRUSS-AUD | B7: Burruss Auditorium | C7: Burruss Hall Auditorium | D7: VT-BURRUSS | E7: N-BURRUSS-E1 | F7: 01-02 | G7: venue | H7: inferred | I7: =IF(OR(H7="official",H7="field_verified"),"CONFIRMED","UNKNOWN") | J7: 3,003-seat auditorium. WARNING: its mapped entrance is the stepped Drillfield front.
A8: POI-SQUIRES-FOOD | B8: Squires Food Court | C8: Squires dining | D8: VT-SQUIRES | E8: N-SQUIRES-E1 | F8: 01 | G8: dining | H8: inferred | I8: =IF(OR(H8="official",H8="field_verified"),"CONFIRMED","UNKNOWN") | J8: Listed as D4 on the 2025 campus map.
A9: POI-CUBE | B9: The Cube | C9: Moss Cube;CFA Cube | D9: VT-CFA | E9: N-CFA-E1 | G9: venue | H9: inferred | I9: =IF(OR(H9="official",H9="field_verified"),"CONFIRMED","UNKNOWN") | J9: Four-storey experimental theatre inside the Center for the Arts.

Sheet Status Updates
A1: asset_id | B1: status | C1: reason | D1: reported_at | E1: expected_end | F1: source | G1: confidence | H1: notes
A2: VT-BURRUSS-ELEV-1 | B2: closed | C2: Maintenance | D2: 2026-09-19T14:00:00-04:00 | E2: 2026-09-19T18:00:00-04:00 | F2: Facilities | G2: official | H2: EXAMPLE ROW from the AccessPath spec. Drives the outage demo.
A3: VT-SQUIRES-ELEV-1 | B3: available | C3: Routine check passed | D3: 2026-09-19T08:15:00-04:00 | F3: Facilities | G3: official | H3: EXAMPLE of a positive confirmation overriding an unknown baseline.
A4: SEG-014 | B4: closed | C4: Alumni Mall resurfacing | D4: 2026-09-15T07:00:00-04:00 | E4: 2026-09-26T17:00:00-04:00 | F4: Facilities | G4: official | H4: EXAMPLE path closure - forces a reroute to Squires via SEG-015/016.
A5: SEG-028 | B5: closed | C5: Mitchell Hall construction site | D5: 2026-08-01T00:00:00-04:00 | E5: 2028-08-01T00:00:00-04:00 | F5: Facilities | G5: official | H5: EXAMPLE long-running closure. A building on the current campus map that cannot be entered at all.
A6: VT-BURRUSS-E2 | B6: step_free | C6: Reported usable by a wheelchair user | D6: 2026-09-17T11:40:00-04:00 | F6: AccessPath user report | G6: community_report | H6: EXAMPLE community report. NOTE: step_free is an accessibility_status, not an operational_status. The spec's status column does not say which vocabulary it draws on. See README item 3.
A7: VT-TORG-ELEV-B3 | B7: unknown | C7: No recent signal | D7: 2026-09-19T00:00:00-04:00 | F7: AccessPath staleness job | G7: inferred | H7: EXAMPLE of an entry ageing out to unknown.

Sheet Sources
A1: source_id | B1: source_name | C1: url | D1: retrieved_date | E1: covers | F1: license | G1: reliability | H1: notes
A2: SRC-01 | B2: CDCD Building Floorplan Mirror (uploaded floorplans.zip) | C2: (local archive, originally cdcd.vt.edu) | D2: 2006-09-07 | E2: 603 floorplan GIFs for 252 buildings + building index | F2: Unknown - third-party mirror, permission not established | G2: Low (20 years stale) | H2: Covers no building constructed after Sept 2006.
A3: SRC-02 | B3: VT Main Campus Map (vt_main_map.pdf, inside the upload) | C3: (local archive) | D3: 2007-01-30 | E3: 116 main-campus buildings with grid refs | F3: Virginia Tech | G3: Low (stale) | H3: Grid references only.
A4: SRC-03 | B4: VT building pages, vt.edu/about/locations/buildings/* | C4: https://www.vt.edu/about/locations/buildings/ | D4: 2026-09-19 | E4: Official name, number, abbreviation, address, grid and COORDINATES | F4: Virginia Tech | G4: High | H4: Source of every coordinate marked OFFICIAL. 13 of 14 pilot buildings.
A5: SRC-04 | B5: VT Blacksburg Campus Map 2025 | C5: https://www.vt.edu/content/dam/vt_edu/maps-locations/blacksburg-map-070225.pdf | D5: 2026-09-19 | E5: The authoritative current building list - what is on campus NOW | F5: Virginia Tech | G5: High | H5: Dated 02 July 2025. Used to build the 'new since 2006' analysis and to catch renames.
A6: SRC-05 | B6: VT Division of Facilities, capital construction projects | C6: https://www.facilities.vt.edu/design-construction/capital-construction/campus-construction-projects/ | D6: 2026-09-19 | E6: Hitt Hall, D&DS, Mitchell Hall, USLB, CID, Upper Quad; ADA-compliance statements; the Infinite Loop | F6: Virginia Tech | G6: High | H6: Basis for the Hitt Hall elevator and Infinite Loop rows.
A7: SRC-06 | B7: Gobblerpedia | C7: https://gobblerpedia.org/ | D7: (undated) | E7: Whittemore 3rd-floor bridges | F7: Community wiki | G7: Low | H7: Treated as community_report.
A8: SRC-07 | B8: VT Accessibility Portal + official Interactive Campus Map | C8: https://accessibility.vt.edu/ | D8: 2026-09-19 | E8: VT ALREADY PUBLISHES accessible entrances, elevators/lifts, curb cuts and accessible-only routing | F8: Virginia Tech | G8: High | H8: THE KEY SOURCE. Layers menu on the interactive map. Built by VT Enterprise GIS with the ADA campus accessibility architect. This is the real confirmed data - go get it.
A9: SRC-08 | B9: VT Facilities GIS data via University Libraries geo-data portal | C9: https://guides.lib.vt.edu/c.php?g=660137&p=4634742 | D9: 2026-09-19 | E9: VT basemap, boundary, BUILDINGS, 5ft contours, road centrelines, parcels | F9: Virginia Tech | G9: High | H9: Downloadable by VT students/faculty/staff FROM A CAMPUS IP. You qualify. Gives real building footprints instead of centroids.
A10: SRC-09 | B10: NOT YET OBTAINED - VT ADA & Accessibility Services / Enterprise GIS | C10: https://accessibility.vt.edu/ | E10: Accessible entrance list, elevator inventory with asset IDs, live outage feed | H10: ACTION: email them. Ask for the accessibility layer behind the interactive map, and the elevator asset ID scheme.
A11: SRC-10 | B11: NOT YET OBTAINED - your own field survey | E11: The only way to get field_verified rows before the hackathon | H11: ACTION: see the Field Survey tab. ~2 hours of walking converts this file from all-unknown to a real demo.

Sheet Field Survey
A1: FIELD SURVEY - turn UNKNOWN into CONFIRMED
A3: Why | B3: Every accessibility value in this workbook is currently a guess. Fifteen confirmed entrances is the difference between a demo that shows real step-free routing and one that shows a grey map.
A4: Time | B4: About two hours on foot for the 15 rows below, walked in the given order. Start at Squires, end at Hitt.
A5: What to record | B5: For each door: is there a step? How many? Is there a ramp or a level approach nearby? Does the door open automatically or need a hard pull?
A6: Deciding step_free | B6: No step at all, or a ramp you could roll up unaided, AND the door can be opened from a seated position. Any lip over about 13 mm is NOT step free - record it as limited and note the height.
A7: limited vs stairs | B7: limited = passable by some wheelchair users but not all (steep ramp, heavy door, narrow width). stairs = steps with no step-free alternative at this door.
A8: How to file it | B8: Fill the last five columns, then copy each finished row's values into the matching row of the Entrances tab and set confidence = field_verified. display_tier flips to CONFIRMED automatically.
A9: Photograph everything | B9: One photo per door. If a judge asks how you know, the photo is the answer.
A10: Do not guess | B10: A blank row is fine. A wrong step_free is how someone ends up stuck at the bottom of a flight of stairs.
A12: walk_order | B12: entrance_id | C12: building | D12: which door | E12: why this one first | F12: step? (y/n) | G12: step_count | H12: ramp or level route nearby? | I12: door opens easily? | J12: your accessibility_status
A13: 1 | B13: VT-SQUIRES-E1 | C13: Squires Student Center | D13: Alumni Mall / west side | E13: Busiest student building in the pilot.
A14: 2 | B14: VT-SQUIRES-E2 | C14: Squires Student Center | D14: College Avenue side | E14: Second door - needed for the perimeter link.
A15: 3 | B15: VT-NEWMAN-LIB-E2 | C15: Newman Library | D15: Alumni Mall / north side | E15: No floorplan exists for this building at all.
A16: 4 | B16: VT-NEWMAN-LIB-E1 | C16: Newman Library | D16: Drillfield (west) side | E16: Same - zero interior data.
A17: 5 | B17: VT-TORGERSEN-E1 | C17: Torgersen Hall | D17: Alumni Mall / south side | E17: Feeds the Torgersen-Newman bridge route.
A18: 6 | B18: VT-TORGERSEN-E2 | C18: Torgersen Hall | D18: North side
A19: 7 | B19: VT-BURRUSS-E2 | C19: Burruss Hall | D19: North side | E19: HIGHEST VALUE ROW. If E2 is step-free, Burruss is reachable; if not, the whole pilot has a hole.
A20: 8 | B20: VT-BURRUSS-E1 | C20: Burruss Hall | D20: Drillfield (east) front | E20: Count the steps so the stairs value stops being a guess.
A21: 9 | B21: VT-MCBRYDE-EN | C21: McBryde Hall | D21: North entrance | E21: VT says all four faces have doors - check which are usable.
A22: 10 | B22: VT-MCBRYDE-EW | C22: McBryde Hall | D22: West entrance
A23: 11 | B23: VT-KELLY-E1 | C23: Kelly Hall | D23: Stanger Street side | E23: 2008 build - no plan anywhere.
A24: 12 | B24: VT-WHITTEMORE-E1 | C24: Whittemore Hall | D24: North side / Perry Street | E24: Also check the 3rd-floor bridges to Durham and Hancock.
A25: 13 | B25: VT-DURHAM-E1 | C25: Durham Hall | D25: Perry Street side
A26: 14 | B26: VT-GOODWIN-E1 | C26: Goodwin Hall | D26: Perry Street side | E26: 2014 build - no plan anywhere.
A27: 15 | B27: VT-HITT-E1 | C27: Hitt Hall | D27: Innovation Plaza | E27: 2024 build. VT claims ADA compliance - verify it, and check the Infinite Loop paving.

Sheet Floorplan Gaps
A1: building_number | B1: building_name | C1: gap_type | D1: on_2025_campus_map | E1: name_in_2006_index | F1: floorplan_files_in_archive | G1: priority | H1: notes
A2: 272 | B2: 417 Clay Street (Cranwell House) | C2: RENAMED_OR_RENUMBERED - plan may be a DIFFERENT building | D2: yes | E2: Cranwell International Center | F2: 3 file(s) | G2: CRITICAL - do not load blindly | H2: Number 272 was 'Cranwell International Center' in 2006. Verify the plan is this building before importing.
A3: 183 | B3: Burrows-Burleson Tennis Center | C3: RENAMED_OR_RENUMBERED - plan may be a DIFFERENT building | D3: yes | E3: Indoor Tennis Courts | F3: 2 file(s) | G3: CRITICAL - do not load blindly | H3: Number 183 was 'Indoor Tennis Courts' in 2006. Verify the plan is this building before importing.
A4: 188 | B4: Center for the Arts | C4: RENAMED_OR_RENUMBERED - plan may be a DIFFERENT building | D4: yes | E4: Shultz Hall | F4: 2 file(s) | G4: CRITICAL - do not load blindly | H4: Number 188 was 'Shultz Hall' in 2006. Verify the plan is this building before importing.
A5: 175 | B5: College of Liberal Arts and Human Sciences Building | C5: RENAMED_OR_RENUMBERED - plan may be a DIFFERENT building | D5: yes | E5: Performing Arts Building | F5: 4 file(s) | G5: CRITICAL - do not load blindly | H5: Number 175 was 'Performing Arts Building' in 2006. Verify the plan is this building before importing.
A6: 196 | B6: Corps Leadership and Military Science Building | C6: RENAMED_OR_RENUMBERED - plan may be a DIFFERENT building | D6: yes | E6: Art and Design Learning Center | F6: 2 file(s) | G6: CRITICAL - do not load blindly | H6: Number 196 was 'Art and Design Learning Center' in 2006. Verify the plan is this building before importing.
A7: 240 | B7: Fleet Services Building | C7: RENAMED_OR_RENUMBERED - plan may be a DIFFERENT building | D7: yes | E7: Motor Pool | F7: 1 file(s) | G7: CRITICAL - do not load blindly | H7: Number 240 was 'Motor Pool' in 2006. Verify the plan is this building before importing.
A8: 158 | B8: Hahn Hall - North Wing | C8: RENAMED_OR_RENUMBERED - plan may be a DIFFERENT building | D8: yes | E8: Chemistry–Physics | F8: 4 file(s) | G8: CRITICAL - do not load blindly | H8: Number 158 was 'Chemistry–Physics' in 2006. Verify the plan is this building before importing.
A9: 30 | B9: Hoge Hall | C9: RENAMED_OR_RENUMBERED - plan may be a DIFFERENT building | D9: yes | E9: Lee Hall | F9: 9 file(s) | G9: CRITICAL - do not load blindly | H9: Number 30 was 'Lee Hall' in 2006. Verify the plan is this building before importing.
A10: 204 | B10: North Chiller Plant | C10: RENAMED_OR_RENUMBERED - plan may be a DIFFERENT building | D10: yes | E10: Air Conditioning Plant | F10: 1 file(s) | G10: CRITICAL - do not load blindly | H10: Number 204 was 'Air Conditioning Plant' in 2006. Verify the plan is this building before importing.
A11: 194 | B11: Smith Career Center | C11: RENAMED_OR_RENUMBERED - plan may be a DIFFERENT building | D11: yes | E11: Career Services Building | F11: 2 file(s) | G11: CRITICAL - do not load blindly | H11: Number 194 was 'Career Services Building' in 2006. Verify the plan is this building before importing.
A12: 184 | B12: Venture Out | C12: RENAMED_OR_RENUMBERED - plan may be a DIFFERENT building | D12: yes | E12: Recreation Area Storage Building | F12: 1 file(s) | G12: CRITICAL - do not load blindly | H12: Number 184 was 'Recreation Area Storage Building' in 2006. Verify the plan is this building before importing.
... A14: 26 | B14: Whitehurst Hall | C14: RENAMED_OR_RENUMBERED - plan may be a DIFFERENT building | D14: yes | E14: Barringer Hall | F14: 4 file(s) | G14: CRITICAL - do not load blindly | H14: Number 26 was 'Barringer Hall' in 2006. Verify the plan is this building before importing.
A15: 2140 | B15: APEX Center for Entrepreneurs | C15: new_since_2006 | D15: yes | E15: not listed | G15: HIGH - on the 2025 campus map | H15: Built, renamed or renumbered after the 2006 archive.
A16: 33 | B16: Ambler Johnston Hall - East Wing | C16: new_since_2006 | D16: yes | E16: not listed | G16: HIGH - on the 2025 campus map | H16: Built, renamed or renumbered after the 2006 archive.
A17: 173 | B17: Bishop-Favrao Hall | C17: new_since_2006 | D17: yes | E17: not listed | G17: HIGH - on the 2025 campus map | H17: Built, renamed or renumbered after the 2006 archive.
A18: 159 | B18: Classroom Building | C18: new_since_2006 | D18: yes | E18: not listed | G18: HIGH - on the 2025 campus map | H18: Built, renamed or renumbered after the 2006 archive.
A19: 0056 | B19: Creativity and Innovation District (CID) / Living Learning Community | C19: new_since_2006 | D19: yes | E19: not listed | G19: HIGH - on the 2025 campus map | H19: Built, renamed or renumbered after the 2006 archive.
A20: 137 | B20: Data and Decisions Sciences Building | C20: new_since_2006 | D20: yes | E20: not listed | G20: HIGH - on the 2025 campus map | H20: Built, renamed or renumbered after the 2006 archive.
A21: D2 | B21: Dietrick Hall | C21: new_since_2006 | D21: yes | E21: not listed | G21: HIGH - on the 2025 campus map | H21: Built, renamed or renumbered after the 2006 archive.
A22: 390 | B22: Duck Pond Gazebo | C22: new_since_2006 | D22: yes | E22: not listed | G22: HIGH - on the 2025 campus map | H22: Built, renamed or renumbered after the 2006 archive.
A23: 185V | B23: English Field at Union Park | C23: new_since_2006 | D23: yes | E23: not listed | G23: HIGH - on the 2025 campus map | H23: Built, renamed or renumbered after the 2006 archive.
A24: 184C | B24: Field House | C24: new_since_2006 | D24: yes | E24: not listed | G24: HIGH - on the 2025 campus map | H24: Built, renamed or renumbered after the 2006 archive.
A25: 187B | B25: Football Locker Room | C25: new_since_2006 | D25: yes | E25: not listed | G25: HIGH - on the 2025 campus map | H25: Built, renamed or renumbered after the 2006 archive.
A26: 2317 | B26: Gilbert Place | C26: new_since_2006 | D26: yes | E26: not listed | G26: HIGH - on the 2025 campus map | H26: Built, renamed or renumbered after the 2006 archive.
... A190: 0490 | B190: Young Stock Barn | C190: listed_2006_but_no_plan_file | D190: no | E190: Young Stock Barn | G190: LOW - not on the 2025 campus map (farm, storage, outlying or demolished) | H190: VT-owned in 2006; may no longer exist.
